============================= test session starts ==============================
platform darwin -- Python 3.12.11, pytest-8.4.1, pluggy-1.6.0 -- /Users/jonah/Library/Caches/pypoetry/virtualenvs/omnibase-core-Twd7t-Wn-py3.12/bin/python
cachedir: .pytest_cache
rootdir: /Volumes/PRO-G40/Code/omnibase_core/tests
configfile: pytest.ini
plugins: asyncio-0.25.3, anyio-4.10.0, cov-7.0.0
asyncio: mode=Mode.STRICT, asyncio_default_fixture_loop_scope=None
collecting ... collected 0 items / 3 errors

==================================== ERRORS ====================================
_______ ERROR collecting unit/models/discovery/test_discovery_events.py ________
ImportError while importing test module '/Volumes/PRO-G40/Code/omnibase_core/tests/unit/models/discovery/test_discovery_events.py'.
Hint: make sure your test modules/packages have valid Python names.
Traceback:
/opt/homebrew/Cellar/python@3.12/3.12.11/Frameworks/Python.framework/Versions/3.12/lib/python3.12/importlib/__init__.py:90: in import_module
    return _bootstrap._gcd_import(name[level:], package, level)
           ^^^^^^^^^^^^^^^^^^^^^^^^^^^^^^^^^^^^^^^^^^^^^^^^^^^^
tests/unit/models/discovery/test_discovery_events.py:7: in <module>
    from omnibase_core.models.core.model_semver import ModelSemVer
src/omnibase_core/models/__init__.py:3: in <module>
    from omnibase_core.models.common.model_error_context import ModelErrorContext
src/omnibase_core/models/common/__init__.py:12: in <module>
    from .model_validation_result import (
src/omnibase_core/models/common/model_validation_result.py:8: in <module>
    from omnibase_core.models.common.model_validation_metadata import (
src/omnibase_core/models/common/model_validation_metadata.py:3: in <module>
    from omnibase_core.models.core.model_semver import ModelSemVer
src/omnibase_core/models/core/__init__.py:14: in <module>
    from .model_configuration_base import ModelConfigurationBase
src/omnibase_core/models/core/model_configuration_base.py:34: in <module>
    from omnibase_core.models.infrastructure.model_result import ModelResult
src/omnibase_core/models/infrastructure/__init__.py:15: in <module>
    from .model_metric import ModelMetric
src/omnibase_core/models/infrastructure/model_metric.py:27: in <module>
    from omnibase_core.models.metadata.model_metadata_value import ModelMetadataValue
src/omnibase_core/models/metadata/__init__.py:24: in <module>
    from .model_metadata_node_analytics import ModelMetadataNodeAnalytics
src/omnibase_core/models/metadata/model_metadata_node_analytics.py:30: in <module>
    from omnibase_core.models.infrastructure.model_metrics_data import ModelMetricsData
src/omnibase_core/models/infrastructure/model_metrics_data.py:31: in <module>
    from .model_metric import ModelMetric
E   ImportError: cannot import name 'ModelMetric' from partially initialized module 'omnibase_core.models.infrastructure.model_metric' (most likely due to a circular import) (/Volumes/PRO-G40/Code/omnibase_core/src/omnibase_core/models/infrastructure/model_metric.py)
_ ERROR collecting unit/models/discovery/test_request_response_introspection.py _
ImportError while importing test module '/Volumes/PRO-G40/Code/omnibase_core/tests/unit/models/discovery/test_request_response_introspection.py'.
Hint: make sure your test modules/packages have valid Python names.
Traceback:
/opt/homebrew/Cellar/python@3.12/3.12.11/Frameworks/Python.framework/Versions/3.12/lib/python3.12/importlib/__init__.py:90: in import_module
    return _bootstrap._gcd_import(name[level:], package, level)
           ^^^^^^^^^^^^^^^^^^^^^^^^^^^^^^^^^^^^^^^^^^^^^^^^^^^^
tests/unit/models/discovery/test_request_response_introspection.py:13: in <module>
    from omnibase_core.mixins.mixin_request_response_introspection import (
src/omnibase_core/mixins/__init__.py:18: in <module>
    from omnibase_core.mixins.mixin_canonical_serialization import (
src/omnibase_core/mixins/mixin_canonical_serialization.py:35: in <module>
    from omnibase_core.models.core.model_project_metadata import get_canonical_versions
src/omnibase_core/models/core/model_project_metadata.py:48: in <module>
    from omnibase_core.models.metadata.model_metadata_constants import (
src/omnibase_core/models/__init__.py:15: in <module>
    from . import (
src/omnibase_core/models/contracts/__init__.py:3: in <module>
    from omnibase_core.models.core.model_workflow import ModelWorkflow
E   ModuleNotFoundError: No module named 'omnibase_core.models.core.model_workflow'
___ ERROR collecting unit/models/discovery/test_unified_discovery_system.py ____
ImportError while importing test module '/Volumes/PRO-G40/Code/omnibase_core/tests/unit/models/discovery/test_unified_discovery_system.py'.
Hint: make sure your test modules/packages have valid Python names.
Traceback:
/opt/homebrew/Cellar/python@3.12/3.12.11/Frameworks/Python.framework/Versions/3.12/lib/python3.12/importlib/__init__.py:90: in import_module
    return _bootstrap._gcd_import(name[level:], package, level)
           ^^^^^^^^^^^^^^^^^^^^^^^^^^^^^^^^^^^^^^^^^^^^^^^^^^^^
tests/unit/models/discovery/test_unified_discovery_system.py:16: in <module>
    from omnibase_core.models.core.model_onex_event import OnexEventTypeEnum
src/omnibase_core/models/core/model_onex_event.py:14: in <module>
    from .model_onex_event_metadata import ModelOnexEventMetadata
src/omnibase_core/models/core/model_onex_event_metadata.py:4: in <module>
    from omnibase_core.models.core.model_onex_event import ModelOnexEvent
E   ImportError: cannot import name 'ModelOnexEvent' from partially initialized module 'omnibase_core.models.core.model_onex_event' (most likely due to a circular import) (/Volumes/PRO-G40/Code/omnibase_core/src/omnibase_core/models/core/model_onex_event.py)
=========================== short test summary info ============================
ERROR tests/unit/models/discovery/test_discovery_events.py
ERROR tests/unit/models/discovery/test_request_response_introspection.py
ERROR tests/unit/models/discovery/test_unified_discovery_system.py
!!!!!!!!!!!!!!!!!!! Interrupted: 3 errors during collection !!!!!!!!!!!!!!!!!!!!
============================== 3 errors in 1.00s ===============================
